<mujoco model="mjlab scene">
  <compiler angle="radian" meshdir="assets" />
  <size nkey="1" />
  <visual>
    <global azimuth="135" elevation="-25" offwidth="1920" offheight="1080" />
    <quality shadowsize="8192" />
    <headlight ambient="0.3 0.3 0.3" diffuse="0.6 0.6 0.6" specular="0 0 0" />
    <scale forcewidth="0.25" contactwidth="0.4" contactheight="0.15" framelength="5" framewidth="0.3" />
    <rgba haze="0.15 0.25 0.35 1" force="1 0 0 1" />
  </visual>
  <statistic meansize="0.03" />
  <default>
    <default class="robot/main">
      <default class="robot/so101_new_calib">
        <joint armature="0.005" damping="1" frictionloss="0.1" />
        <general biastype="affine" gainprm="50" biasprm="0 -50" />
        <default class="robot/visual">
          <geom type="mesh" contype="0" conaffinity="0" group="2" />
        </default>
        <default class="robot/collision">
          <geom group="3" />
        </default>
      </default>
      <default class="robot/sts3215">
        <joint armature="0.028" damping="0.6" frictionloss="0.052" />
        <geom contype="0" conaffinity="0" />
        <general biastype="affine" gainprm="17.8" biasprm="0 -17.8" />
      </default>
      <default class="robot/backlash">
        <joint limited="true" range="-0.00872665 0.00872665" armature="0.01" damping="0.01" />
      </default>
    </default>
  </default>
  <asset>
    <texture type="2d" colorspace="auto" name="groundplane" builtin="checker" mark="edge" rgb1="0.2 0.3 0.4" rgb2="0.1 0.2 0.3" markrgb="0.8 0.8 0.8" width="300" height="300" />
    <material name="groundplane" texture="groundplane" texuniform="true" texrepeat="4 4" />
    <material name="robot/base_motor_holder_so101_v1_material" rgba="0.964706 0.964706 0.952941 1" />
    <material name="robot/base_so101_v2_material" rgba="0.964706 0.964706 0.952941 1" />
    <material name="robot/sts3215_03a_v1_material" rgba="0.627451 0.627451 0.627451 1" />
    <material name="robot/waveshare_mounting_plate_so101_v2_material" rgba="0.964706 0.964706 0.952941 1" />
    <material name="robot/motor_holder_so101_base_v1_material" rgba="0.964706 0.964706 0.952941 1" />
    <material name="robot/rotation_pitch_so101_v1_material" rgba="0.964706 0.964706 0.952941 1" />
    <material name="robot/upper_arm_so101_v1_material" rgba="0.964706 0.964706 0.952941 1" />
    <material name="robot/under_arm_so101_v1_material" rgba="0.964706 0.964706 0.952941 1" />
    <material name="robot/motor_holder_so101_wrist_v1_material" rgba="0.964706 0.964706 0.952941 1" />
    <material name="robot/sts3215_03a_no_horn_v1_material" rgba="0.627451 0.627451 0.627451 1" />
    <material name="robot/wrist_roll_pitch_so101_v2_material" rgba="0.964706 0.964706 0.952941 1" />
    <material name="robot/wrist_roll_follower_so101_v1_material" rgba="0.964706 0.964706 0.952941 1" />
    <material name="robot/moving_jaw_so101_v1_material" rgba="0.964706 0.964706 0.952941 1" />
    <mesh name="robot/waveshare_mounting_plate_so101_v2" content_type="model/stl" file="assets/waveshare_mounting_plate_so101_v2.stl" />
    <mesh name="robot/sts3215_03a_v1" content_type="model/stl" file="assets/sts3215_03a_v1.stl" />
    <mesh name="robot/motor_holder_so101_base_v1" content_type="model/stl" file="assets/motor_holder_so101_base_v1.stl" />
    <mesh name="robot/wrist_roll_follower_so101_v1" content_type="model/stl" file="assets/wrist_roll_follower_so101_v1.stl" />
    <mesh name="robot/moving_jaw_so101_v1" content_type="model/stl" file="assets/moving_jaw_so101_v1.stl" />
    <mesh name="robot/base_motor_holder_so101_v1" content_type="model/stl" file="assets/base_motor_holder_so101_v1.stl" />
    <mesh name="robot/upper_arm_so101_v1" content_type="model/stl" file="assets/upper_arm_so101_v1.stl" />
    <mesh name="robot/wrist_roll_pitch_so101_v2" content_type="model/stl" file="assets/wrist_roll_pitch_so101_v2.stl" />
    <mesh name="robot/under_arm_so101_v1" content_type="model/stl" file="assets/under_arm_so101_v1.stl" />
    <mesh name="robot/rotation_pitch_so101_v1" content_type="model/stl" file="assets/rotation_pitch_so101_v1.stl" />
    <mesh name="robot/motor_holder_so101_wrist_v1" content_type="model/stl" file="assets/motor_holder_so101_wrist_v1.stl" />
    <mesh name="robot/sts3215_03a_no_horn_v1" content_type="model/stl" file="assets/sts3215_03a_no_horn_v1.stl" />
    <mesh name="robot/base_so101_v2" content_type="model/stl" file="assets/base_so101_v2.stl" />
    <mesh name="container/container_visual" content_type="model/stl" file="/home/y423610m/ros2_lerobot/src/lerobot_robots_description/meshes/container_visual.stl" />
    <mesh name="container/container_collision" content_type="model/stl" file="/home/y423610m/ros2_lerobot/src/lerobot_robots_description/meshes/container_collision.stl" />
  </asset>
  <worldbody>
    <light name="sun" pos="0 0 1.5" dir="0 0 -1" type="directional" />
    <body name="terrain">
      <geom name="terrain" size="0 0 0.01" type="plane" material="groundplane" />
    </body>
    <body name="table/mocap_base" mocap="true">
      <body name="table/table">
        <geom name="table/table_top" size="0.6 0.275 0.025" pos="0 0 0.8" type="box" rgba="0.6 0.5 0.4 1" />
      </body>
    </body>
    <body name="robot/mocap_base" mocap="true">
      <body name="robot/base" childclass="robot/so101_new_calib" pos="-0.4 0.25 0.825" quat="-0.707107 0 0 0.707107">
        <inertial pos="0.0137179 -5.19711e-05 0.0334843" quat="0.420519 0.558762 0.57198 0.428704" mass="0.147" diaginertia="0.000136127 0.000131807 0.000113233" />
        <geom class="robot/visual" pos="-0.00636471 -9.94414e-05 -0.0024" quat="0.5 0.5 0.5 0.5" material="robot/base_motor_holder_so101_v1_material" mesh="robot/base_motor_holder_so101_v1" />
        <geom class="robot/visual" pos="-0.00636471 -8.97657e-09 -0.0024" quat="0.5 0.5 0.5 0.5" material="robot/base_so101_v2_material" mesh="robot/base_so101_v2" />
        <geom class="robot/visual" pos="0.0263353 -8.97657e-09 0.0437" quat="1 0 0 0" material="robot/sts3215_03a_v1_material" mesh="robot/sts3215_03a_v1" />
        <geom class="robot/visual" pos="-0.0309827 -0.000199441 0.0474" quat="0.5 0.5 0.5 0.5" material="robot/waveshare_mounting_plate_so101_v2_material" mesh="robot/waveshare_mounting_plate_so101_v2" />
        <site name="robot/baseframe" pos="0 0 0" quat="1 0 0 0" group="3" />
        <body name="robot/shoulder" pos="0.0388353 -8.97657e-09 0.0624" quat="0 0 -1 0">
          <inertial pos="-0.0307604 -1.66727e-05 -0.0252713" quat="0.999865 0.00149563 0.0097084 0.0132043" mass="0.100006" diaginertia="8.37836e-05 8.10388e-05 2.39552e-05" />
          <joint name="robot/shoulder_pan" class="robot/sts3215" pos="0 0 0" axis="0 0 1" range="-1.91986 1.91986" />
          <geom class="robot/visual" pos="-0.0303992 0.000422241 -0.0417" quat="0.5 0.5 0.5 -0.5" material="robot/sts3215_03a_v1_material" mesh="robot/sts3215_03a_v1" />
          <geom class="robot/collision" pos="-0.0303992 0.000422241 -0.0417" quat="0.5 0.5 0.5 -0.5" type="mesh" material="robot/sts3215_03a_v1_material" mesh="robot/sts3215_03a_v1" />
          <geom class="robot/visual" pos="-0.0675992 -0.000177759 0.0158499" quat="0.5 0.5 -0.5 0.5" material="robot/motor_holder_so101_base_v1_material" mesh="robot/motor_holder_so101_base_v1" />
          <geom class="robot/collision" pos="-0.0675992 -0.000177759 0.0158499" quat="0.5 0.5 -0.5 0.5" type="mesh" material="robot/motor_holder_so101_base_v1_material" mesh="robot/motor_holder_so101_base_v1" />
          <geom class="robot/visual" pos="0.0122008 2.22413e-05 0.0464" quat="0.707107 -0.707107 0 0" material="robot/rotation_pitch_so101_v1_material" mesh="robot/rotation_pitch_so101_v1" />
          <geom class="robot/collision" pos="0.0122008 2.22413e-05 0.0464" quat="0.707107 -0.707107 0 0" type="mesh" material="robot/rotation_pitch_so101_v1_material" mesh="robot/rotation_pitch_so101_v1" />
          <body name="robot/upper_arm" pos="-0.0303992 -0.0182778 -0.0542" quat="0.5 -0.5 -0.5 -0.5">
            <inertial pos="-0.0898471 -0.00838224 0.0184089" quat="0.453195 0.454063 0.541891 0.542951" mass="0.103" diaginertia="0.000150873 0.000142487 3.72451e-05" />
            <joint name="robot/shoulder_lift" class="robot/sts3215" pos="0 0 0" axis="0 0 1" range="-1.74533 1.74533" />
            <geom class="robot/visual" pos="-0.11257 -0.0155 0.0187" quat="0 -0.707107 0.707107 0" material="robot/sts3215_03a_v1_material" mesh="robot/sts3215_03a_v1" />
            <geom class="robot/collision" pos="-0.11257 -0.0155 0.0187" quat="0 -0.707107 0.707107 0" type="mesh" material="robot/sts3215_03a_v1_material" mesh="robot/sts3215_03a_v1" />
            <geom class="robot/visual" pos="-0.065085 0.012 0.0182" quat="0 1 0 0" material="robot/upper_arm_so101_v1_material" mesh="robot/upper_arm_so101_v1" />
            <geom class="robot/collision" pos="-0.065085 0.012 0.0182" quat="0 1 0 0" type="mesh" material="robot/upper_arm_so101_v1_material" mesh="robot/upper_arm_so101_v1" />
            <body name="robot/lower_arm" pos="-0.11257 -0.028 0" quat="0.707107 0 0 0.707107">
              <inertial pos="-0.0980701 0.00324376 0.0182831" quat="0.510729 0.517006 0.487966 0.483477" mass="0.104" diaginertia="0.000160262 0.000145304 2.83125e-05" />
              <joint name="robot/elbow_flex" class="robot/sts3215" pos="0 0 0" axis="0 0 1" range="-1.69 1.69" />
              <geom class="robot/visual" pos="-0.0648499 -0.032 0.0182" quat="0 1 0 0" material="robot/under_arm_so101_v1_material" mesh="robot/under_arm_so101_v1" />
              <geom class="robot/collision" pos="-0.0648499 -0.032 0.0182" quat="0 1 0 0" type="mesh" material="robot/under_arm_so101_v1_material" mesh="robot/under_arm_so101_v1" />
              <geom class="robot/visual" pos="-0.0648499 -0.032 0.018" quat="0 -1 0 0" material="robot/motor_holder_so101_wrist_v1_material" mesh="robot/motor_holder_so101_wrist_v1" />
              <geom class="robot/collision" pos="-0.0648499 -0.032 0.018" quat="0 -1 0 0" type="mesh" material="robot/motor_holder_so101_wrist_v1_material" mesh="robot/motor_holder_so101_wrist_v1" />
              <geom class="robot/visual" pos="-0.1224 0.0052 0.0187" quat="0 0 1 0" material="robot/sts3215_03a_v1_material" mesh="robot/sts3215_03a_v1" />
              <geom class="robot/collision" pos="-0.1224 0.0052 0.0187" quat="0 0 1 0" type="mesh" material="robot/sts3215_03a_v1_material" mesh="robot/sts3215_03a_v1" />
              <body name="robot/wrist" pos="-0.1349 0.0052 0" quat="0.707107 0 0 -0.707107">
                <inertial pos="-0.000103312 -0.0386143 0.0281156" quat="0.967143 0.254226 0.00162226 -0.000146307" mass="0.079" diaginertia="3.68265e-05 2.74474e-05 1.89434e-05" />
                <joint name="robot/wrist_flex" class="robot/sts3215" pos="0 0 0" axis="0 0 1" range="-1.65806 1.65806" />
                <geom class="robot/visual" pos="0 -0.0424 0.0306" quat="0.5 0.5 0.5 -0.5" material="robot/sts3215_03a_no_horn_v1_material" mesh="robot/sts3215_03a_no_horn_v1" />
                <geom class="robot/collision" pos="0 -0.0424 0.0306" quat="0.5 0.5 0.5 -0.5" type="mesh" material="robot/sts3215_03a_no_horn_v1_material" mesh="robot/sts3215_03a_no_horn_v1" />
                <geom class="robot/visual" pos="0 -0.028 0.0181" quat="0.5 -0.5 -0.5 -0.5" material="robot/wrist_roll_pitch_so101_v2_material" mesh="robot/wrist_roll_pitch_so101_v2" />
                <geom class="robot/collision" pos="0 -0.028 0.0181" quat="0.5 -0.5 -0.5 -0.5" type="mesh" material="robot/wrist_roll_pitch_so101_v2_material" mesh="robot/wrist_roll_pitch_so101_v2" />
                <site name="robot/ee_wrist" pos="0.012 -0.145 0.02" quat="0.5 0.5 0.5 0.5" group="3" />
                <site name="robot/ee_wrist_base" pos="-0.02 -0.09 0.02" quat="0.5 0.5 0.5 0.5" group="3" />
                <camera name="robot/hand_eye" pos="0 -0.08 0.06" quat="0.92388 -0.382683 0 0" />
                <body name="robot/gripper" pos="0 -0.0611 0.0181" quat="0.0172091 -0.0172091 0.706897 0.706897">
                  <inertial pos="0.000213627 0.000245138 -0.025187" quat="0.600717 0.355993 0.35863 0.61951" mass="0.087" diaginertia="4.33735e-05 3.77229e-05 2.42839e-05" />
                  <joint name="robot/wrist_roll" class="robot/sts3215" pos="0 0 0" axis="0 0 1" range="-2.74385 2.84121" />
                  <geom class="robot/visual" pos="0.0077 0.0001 -0.0234" quat="0.707107 -0.707107 0 0" material="robot/sts3215_03a_v1_material" mesh="robot/sts3215_03a_v1" />
                  <geom class="robot/collision" pos="0.0077 0.0001 -0.0234" quat="0.707107 -0.707107 0 0" type="mesh" material="robot/sts3215_03a_v1_material" mesh="robot/sts3215_03a_v1" />
                  <geom class="robot/visual" pos="0 -0.000218214 0.000949706" quat="0 1 0 0" material="robot/wrist_roll_follower_so101_v1_material" mesh="robot/wrist_roll_follower_so101_v1" />
                  <geom name="robot/gripper_finger_collision_outer" class="robot/collision" size="0.0025 0.012 0.04" pos="-0.025 0 -0.06" quat="0.988771 0 -0.149438 0" type="box" />
                  <geom name="robot/gripper_finger_collision_inner" class="robot/collision" size="0.0025 0.01 0.035" pos="-0.013 0 -0.06" quat="0.99952 0 -0.030995 0" type="box" />
                  <geom class="robot/collision" size="0.035 0.025 0.02" pos="-0.0025 0 -0.025" type="box" />
                  <site name="robot/gripperframe" pos="-0.0079 -0.000218121 -0.0981274" quat="0.707107 0 0.707107 0" group="3" />
                  <body name="robot/moving_jaw_so101_v1" pos="0.0202 0.0188 -0.0234" quat="0.707107 0.707107 -1.85362e-08 1.85362e-08">
                    <inertial pos="-0.00157495 -0.0300244 0.0192755" quat="0.695265 0.717965 -0.0245618 -0.0230097" mass="0.012" diaginertia="6.63582e-06 5.29092e-06 1.86523e-06" />
                    <joint name="robot/gripper" class="robot/sts3215" pos="0 0 0" axis="0 0 1" range="-0.174533 1.74533" />
                    <geom class="robot/visual" pos="0 0 0.0189" quat="1 0 0 0" material="robot/moving_jaw_so101_v1_material" mesh="robot/moving_jaw_so101_v1" />
                    <geom name="robot/moving_jaw_finger_collision_outer" class="robot/collision" size="0.0025 0.04 0.012" pos="-0.001 -0.04 0.02" quat="0.995004 0 0 -0.0998334" type="box" />
                    <geom name="robot/moving_jaw_finger_collision_inner" class="robot/collision" size="0.0025 0.035 0.01" pos="-0.008 -0.04 0.02" quat="0.99875 0 0 -0.0499792" type="box" />
                    <site name="robot/ee_gripper" pos="-0.005 -0.061 0.02" quat="0.5 0.5 0.5 0.5" group="3" />
                  </body>
                </body>
              </body>
            </body>
          </body>
        </body>
      </body>
    </body>
    <body name="block/block">
      <joint name="block/block_freejoint" type="free" />
      <geom name="block/block_geom" size="0.015 0.015 0.015" type="box" friction="1.5 0.5 0.5" mass="0.05" rgba="0.9 0.3 0.1 1" />
      <site name="block/block_site" pos="0 0 0" size="0.003" />
    </body>
    <body name="container/container">
      <joint name="container/container_freejoint" type="free" />
      <geom name="container/container_vis" type="mesh" contype="0" conaffinity="0" mass="0" rgba="0.1 0.8 0.3 0.35" mesh="container/container_visual" />
      <geom name="container/container_collision" type="mesh" mass="0.15" rgba="0 0 0 0" mesh="container/container_collision" />
      <site name="container/container_site" pos="0 0 0.023" size="0.003" />
    </body>
  </worldbody>
  <actuator>
    <general name="robot/shoulder_pan" class="robot/sts3215" joint="robot/shoulder_pan" ctrlrange="-1.91986 1.91986" forcerange="-3.35 3.35" />
    <general name="robot/shoulder_lift" class="robot/sts3215" joint="robot/shoulder_lift" ctrlrange="-1.74533 1.74533" forcerange="-3.35 3.35" />
    <general name="robot/elbow_flex" class="robot/sts3215" joint="robot/elbow_flex" ctrlrange="-1.69 1.69" forcerange="-3.35 3.35" />
    <general name="robot/wrist_flex" class="robot/sts3215" joint="robot/wrist_flex" ctrlrange="-1.65806 1.65806" forcerange="-3.35 3.35" />
    <general name="robot/wrist_roll" class="robot/sts3215" joint="robot/wrist_roll" ctrlrange="-2.74385 2.84121" forcerange="-3.35 3.35" />
    <general name="robot/gripper" class="robot/sts3215" joint="robot/gripper" ctrlrange="-0.17453 1.74533" forcerange="-3.35 3.35" />
  </actuator>
  <keyframe>
    <key name="init_state" qpos="0 -0.3 0.6 0.3 0 0.02 0.3 0 0.841 1 0 0 0 -0.4 -0.1 0.826 1 0 0 0" ctrl="0 -0.3 0.6 0.3 0 0.02" />
  </keyframe>
</mujoco>
